[2025-07-24T17:34:33.731+0000] {taskinstance.py:1956} INFO - Dependencies all met for dep_context=non-requeueable deps ti=<TaskInstance: tunestream_full_etl_dag.stage_songs manual__2025-07-24T17:29:13.467005+00:00 [queued]>
[2025-07-24T17:34:33.764+0000] {taskinstance.py:1956} INFO - Dependencies all met for dep_context=requeueable deps ti=<TaskInstance: tunestream_full_etl_dag.stage_songs manual__2025-07-24T17:29:13.467005+00:00 [queued]>
[2025-07-24T17:34:33.773+0000] {taskinstance.py:2170} INFO - Starting attempt 2 of 4
[2025-07-24T17:34:33.912+0000] {taskinstance.py:2191} INFO - Executing <Task(_PythonDecoratedOperator): stage_songs> on 2025-07-24 17:29:13.467005+00:00
[2025-07-24T17:34:33.954+0000] {standard_task_runner.py:60} INFO - Started process 842 to run task
[2025-07-24T17:34:34.020+0000] {standard_task_runner.py:87} INFO - Running: ['***', 'tasks', 'run', 'tunestream_full_etl_dag', 'stage_songs', 'manual__2025-07-24T17:29:13.467005+00:00', '--job-id', '51', '--raw', '--subdir', 'DAGS_FOLDER/step12345.py', '--cfg-path', '/tmp/tmpezcy5774']
[2025-07-24T17:34:34.040+0000] {standard_task_runner.py:88} INFO - Job 51: Subtask stage_songs
[2025-07-24T17:34:34.399+0000] {task_command.py:423} INFO - Running <TaskInstance: tunestream_full_etl_dag.stage_songs manual__2025-07-24T17:29:13.467005+00:00 [running]> on host 737498b59352
[2025-07-24T17:34:35.142+0000] {taskinstance.py:2480} INFO - Exporting env vars: AIRFLOW_CTX_DAG_OWNER='***' AIRFLOW_CTX_DAG_ID='tunestream_full_etl_dag' AIRFLOW_CTX_TASK_ID='stage_songs' AIRFLOW_CTX_EXECUTION_DATE='2025-07-24T17:29:13.467005+00:00' AIRFLOW_CTX_TRY_NUMBER='2' AIRFLOW_CTX_DAG_RUN_ID='manual__2025-07-24T17:29:13.467005+00:00'
[2025-07-24T17:34:35.440+0000] {base.py:83} INFO - Using connection ID 'postgres_local' for task execution.
[2025-07-24T17:34:35.572+0000] {taskinstance.py:2698} ERROR - Task failed with exception
Traceback (most recent call last):
  File "/home/airflow/.local/lib/python3.8/site-packages/airflow/models/taskinstance.py", line 433, in _execute_task
    result = execute_callable(context=context, **execute_callable_kwargs)
  File "/home/airflow/.local/lib/python3.8/site-packages/airflow/decorators/base.py", line 241, in execute
    return_value = super().execute(context)
  File "/home/airflow/.local/lib/python3.8/site-packages/airflow/operators/python.py", line 199, in execute
    return_value = self.execute_callable()
  File "/home/airflow/.local/lib/python3.8/site-packages/airflow/operators/python.py", line 216, in execute_callable
    return self.python_callable(*self.op_args, **self.op_kwargs)
  File "/opt/airflow/dags/step12345.py", line 145, in stage_songs_task
    json_to_sql("postgres_local","staging_songs",SONG_DATA_PATH,song_columns)
  File "/opt/airflow/dags/step12345.py", line 73, in json_to_sql
    conn = postgres_hook.get_conn()
  File "/home/airflow/.local/lib/python3.8/site-packages/airflow/providers/postgres/hooks/postgres.py", line 158, in get_conn
    self.conn = psycopg2.connect(**conn_args)
  File "/home/airflow/.local/lib/python3.8/site-packages/psycopg2/__init__.py", line 122, in connect
    conn = _connect(dsn, connection_factory=connection_factory, **kwasync)
psycopg2.OperationalError: connection to server at "host.docker.internal" (192.168.65.254), port 5432 failed: FATAL:  password authentication failed for user "postgres"

[2025-07-24T17:34:35.600+0000] {taskinstance.py:1138} INFO - Marking task as UP_FOR_RETRY. dag_id=tunestream_full_etl_dag, task_id=stage_songs, execution_date=20250724T172913, start_date=20250724T173433, end_date=20250724T173435
[2025-07-24T17:34:35.662+0000] {standard_task_runner.py:107} ERROR - Failed to execute job 51 for task stage_songs (connection to server at "host.docker.internal" (192.168.65.254), port 5432 failed: FATAL:  password authentication failed for user "postgres"
; 842)
[2025-07-24T17:34:35.696+0000] {local_task_job_runner.py:234} INFO - Task exited with return code 1
[2025-07-24T17:34:35.752+0000] {taskinstance.py:3280} INFO - 0 downstream tasks scheduled from follow-on schedule check
