[2025-07-24T17:29:20.462+0000] {taskinstance.py:1956} INFO - Dependencies all met for dep_context=non-requeueable deps ti=<TaskInstance: tunestream_full_etl_dag.stage_events manual__2025-07-24T17:29:13.467005+00:00 [queued]>
[2025-07-24T17:29:20.501+0000] {taskinstance.py:1956} INFO - Dependencies all met for dep_context=requeueable deps ti=<TaskInstance: tunestream_full_etl_dag.stage_events manual__2025-07-24T17:29:13.467005+00:00 [queued]>
[2025-07-24T17:29:20.511+0000] {taskinstance.py:2170} INFO - Starting attempt 1 of 4
[2025-07-24T17:29:20.587+0000] {taskinstance.py:2191} INFO - Executing <Task(_PythonDecoratedOperator): stage_events> on 2025-07-24 17:29:13.467005+00:00
[2025-07-24T17:29:20.622+0000] {standard_task_runner.py:60} INFO - Started process 751 to run task
[2025-07-24T17:29:20.667+0000] {standard_task_runner.py:87} INFO - Running: ['***', 'tasks', 'run', 'tunestream_full_etl_dag', 'stage_events', 'manual__2025-07-24T17:29:13.467005+00:00', '--job-id', '48', '--raw', '--subdir', 'DAGS_FOLDER/step12345.py', '--cfg-path', '/tmp/tmpf8x2c5y4']
[2025-07-24T17:29:20.711+0000] {standard_task_runner.py:88} INFO - Job 48: Subtask stage_events
[2025-07-24T17:29:20.886+0000] {task_command.py:423} INFO - Running <TaskInstance: tunestream_full_etl_dag.stage_events manual__2025-07-24T17:29:13.467005+00:00 [running]> on host 737498b59352
[2025-07-24T17:29:21.294+0000] {taskinstance.py:2480} INFO - Exporting env vars: AIRFLOW_CTX_DAG_OWNER='***' AIRFLOW_CTX_DAG_ID='tunestream_full_etl_dag' AIRFLOW_CTX_TASK_ID='stage_events' AIRFLOW_CTX_EXECUTION_DATE='2025-07-24T17:29:13.467005+00:00' AIRFLOW_CTX_TRY_NUMBER='1' AIRFLOW_CTX_DAG_RUN_ID='manual__2025-07-24T17:29:13.467005+00:00'
[2025-07-24T17:29:21.404+0000] {taskinstance.py:2698} ERROR - Task failed with exception
Traceback (most recent call last):
  File "/home/airflow/.local/lib/python3.8/site-packages/airflow/models/taskinstance.py", line 433, in _execute_task
    result = execute_callable(context=context, **execute_callable_kwargs)
  File "/home/airflow/.local/lib/python3.8/site-packages/airflow/decorators/base.py", line 241, in execute
    return_value = super().execute(context)
  File "/home/airflow/.local/lib/python3.8/site-packages/airflow/operators/python.py", line 199, in execute
    return_value = self.execute_callable()
  File "/home/airflow/.local/lib/python3.8/site-packages/airflow/operators/python.py", line 216, in execute_callable
    return self.python_callable(*self.op_args, **self.op_kwargs)
  File "/opt/airflow/dags/step12345.py", line 150, in stage_events_task
    json_to_sql("postgres_local","staging_events",LOG_DATA_PATH,event_columns)
  File "/opt/airflow/dags/step12345.py", line 73, in json_to_sql
    conn = postgres_hook.get_conn()
  File "/home/airflow/.local/lib/python3.8/site-packages/airflow/providers/postgres/hooks/postgres.py", line 128, in get_conn
    conn = deepcopy(self.connection or self.get_connection(conn_id))
  File "/home/airflow/.local/lib/python3.8/site-packages/airflow/hooks/base.py", line 82, in get_connection
    conn = Connection.get_connection_from_secrets(conn_id)
  File "/home/airflow/.local/lib/python3.8/site-packages/airflow/models/connection.py", line 479, in get_connection_from_secrets
    raise AirflowNotFoundException(f"The conn_id `{conn_id}` isn't defined")
airflow.exceptions.AirflowNotFoundException: The conn_id `postgres_local` isn't defined
[2025-07-24T17:29:21.414+0000] {taskinstance.py:1138} INFO - Marking task as UP_FOR_RETRY. dag_id=tunestream_full_etl_dag, task_id=stage_events, execution_date=20250724T172913, start_date=20250724T172920, end_date=20250724T172921
[2025-07-24T17:29:21.493+0000] {standard_task_runner.py:107} ERROR - Failed to execute job 48 for task stage_events (The conn_id `postgres_local` isn't defined; 751)
[2025-07-24T17:29:21.548+0000] {local_task_job_runner.py:234} INFO - Task exited with return code 1
[2025-07-24T17:29:21.763+0000] {taskinstance.py:3280} INFO - 0 downstream tasks scheduled from follow-on schedule check
