[2025-07-24T18:17:44.887+0000] {taskinstance.py:1956} INFO - Dependencies all met for dep_context=non-requeueable deps ti=<TaskInstance: tunestream_full_etl_dag.load_user_dim_table manual__2025-07-24T18:17:21.846820+00:00 [queued]>
[2025-07-24T18:17:44.918+0000] {taskinstance.py:1956} INFO - Dependencies all met for dep_context=requeueable deps ti=<TaskInstance: tunestream_full_etl_dag.load_user_dim_table manual__2025-07-24T18:17:21.846820+00:00 [queued]>
[2025-07-24T18:17:44.926+0000] {taskinstance.py:2170} INFO - Starting attempt 1 of 4
[2025-07-24T18:17:45.038+0000] {taskinstance.py:2191} INFO - Executing <Task(_PythonDecoratedOperator): load_user_dim_table> on 2025-07-24 18:17:21.846820+00:00
[2025-07-24T18:17:45.080+0000] {standard_task_runner.py:60} INFO - Started process 1568 to run task
[2025-07-24T18:17:45.100+0000] {standard_task_runner.py:87} INFO - Running: ['***', 'tasks', 'run', 'tunestream_full_etl_dag', 'load_user_dim_table', 'manual__2025-07-24T18:17:21.846820+00:00', '--job-id', '79', '--raw', '--subdir', 'DAGS_FOLDER/step12345.py', '--cfg-path', '/tmp/tmpme6zxt4q']
[2025-07-24T18:17:45.110+0000] {standard_task_runner.py:88} INFO - Job 79: Subtask load_user_dim_table
[2025-07-24T18:17:45.321+0000] {task_command.py:423} INFO - Running <TaskInstance: tunestream_full_etl_dag.load_user_dim_table manual__2025-07-24T18:17:21.846820+00:00 [running]> on host 737498b59352
[2025-07-24T18:17:45.591+0000] {taskinstance.py:2480} INFO - Exporting env vars: AIRFLOW_CTX_DAG_OWNER='***' AIRFLOW_CTX_DAG_ID='tunestream_full_etl_dag' AIRFLOW_CTX_TASK_ID='load_user_dim_table' AIRFLOW_CTX_EXECUTION_DATE='2025-07-24T18:17:21.846820+00:00' AIRFLOW_CTX_TRY_NUMBER='1' AIRFLOW_CTX_DAG_RUN_ID='manual__2025-07-24T18:17:21.846820+00:00'
[2025-07-24T18:17:45.600+0000] {logging_mixin.py:188} INFO - Executing transformation for table: users
[2025-07-24T18:17:45.634+0000] {base.py:83} INFO - Using connection ID 'postgres_local' for task execution.
[2025-07-24T18:17:45.650+0000] {sql.py:450} INFO - Running statement: TRUNCATE TABLE users; INSERT INTO users 
        SELECT distinct userid, firstname, lastname, gender, level
        FROM staging_events
        WHERE page='NextSong' AND userid IS NOT NULL
    , parameters: None
[2025-07-24T18:17:45.735+0000] {taskinstance.py:2698} ERROR - Task failed with exception
Traceback (most recent call last):
  File "/home/airflow/.local/lib/python3.8/site-packages/airflow/models/taskinstance.py", line 433, in _execute_task
    result = execute_callable(context=context, **execute_callable_kwargs)
  File "/home/airflow/.local/lib/python3.8/site-packages/airflow/decorators/base.py", line 241, in execute
    return_value = super().execute(context)
  File "/home/airflow/.local/lib/python3.8/site-packages/airflow/operators/python.py", line 199, in execute
    return_value = self.execute_callable()
  File "/home/airflow/.local/lib/python3.8/site-packages/airflow/operators/python.py", line 216, in execute_callable
    return self.python_callable(*self.op_args, **self.op_kwargs)
  File "/opt/airflow/dags/step12345.py", line 207, in load_user_dim_task
    load_table("postgres_local", "users", SqlQueries.user_table_insert)
  File "/opt/airflow/dags/step12345.py", line 163, in load_table
    postgres_hook.run(sql_formatted)
  File "/home/airflow/.local/lib/python3.8/site-packages/airflow/providers/common/sql/hooks/sql.py", line 398, in run
    self._run_command(cur, sql_statement, parameters)
  File "/home/airflow/.local/lib/python3.8/site-packages/airflow/providers/common/sql/hooks/sql.py", line 455, in _run_command
    cur.execute(sql_statement)
psycopg2.errors.UniqueViolation: duplicate key value violates unique constraint "users_pkey"
DETAIL:  Key (userid)=(15) already exists.

[2025-07-24T18:17:45.799+0000] {taskinstance.py:1138} INFO - Marking task as UP_FOR_RETRY. dag_id=tunestream_full_etl_dag, task_id=load_user_dim_table, execution_date=20250724T181721, start_date=20250724T181744, end_date=20250724T181745
[2025-07-24T18:17:45.864+0000] {standard_task_runner.py:107} ERROR - Failed to execute job 79 for task load_user_dim_table (duplicate key value violates unique constraint "users_pkey"
DETAIL:  Key (userid)=(15) already exists.
; 1568)
[2025-07-24T18:17:45.927+0000] {local_task_job_runner.py:234} INFO - Task exited with return code 1
[2025-07-24T18:17:45.987+0000] {taskinstance.py:3280} INFO - 0 downstream tasks scheduled from follow-on schedule check
