[2025-07-24T18:34:54.512+0000] {taskinstance.py:1956} INFO - Dependencies all met for dep_context=non-requeueable deps ti=<TaskInstance: tunestream_full_etl_dag.load_user_dim_table manual__2025-07-24T18:04:15.387612+00:00 [queued]>
[2025-07-24T18:34:54.523+0000] {taskinstance.py:1956} INFO - Dependencies all met for dep_context=requeueable deps ti=<TaskInstance: tunestream_full_etl_dag.load_user_dim_table manual__2025-07-24T18:04:15.387612+00:00 [queued]>
[2025-07-24T18:34:54.523+0000] {taskinstance.py:2170} INFO - Starting attempt 4 of 4
[2025-07-24T18:34:54.552+0000] {taskinstance.py:2191} INFO - Executing <Task(_PythonDecoratedOperator): load_user_dim_table> on 2025-07-24 18:04:15.387612+00:00
[2025-07-24T18:34:54.559+0000] {standard_task_runner.py:60} INFO - Started process 1888 to run task
[2025-07-24T18:34:54.584+0000] {standard_task_runner.py:87} INFO - Running: ['***', 'tasks', 'run', 'tunestream_full_etl_dag', 'load_user_dim_table', 'manual__2025-07-24T18:04:15.387612+00:00', '--job-id', '98', '--raw', '--subdir', 'DAGS_FOLDER/step12345.py', '--cfg-path', '/tmp/tmpoqpyi24d']
[2025-07-24T18:34:54.596+0000] {standard_task_runner.py:88} INFO - Job 98: Subtask load_user_dim_table
[2025-07-24T18:34:54.747+0000] {task_command.py:423} INFO - Running <TaskInstance: tunestream_full_etl_dag.load_user_dim_table manual__2025-07-24T18:04:15.387612+00:00 [running]> on host 737498b59352
[2025-07-24T18:34:54.932+0000] {taskinstance.py:2480} INFO - Exporting env vars: AIRFLOW_CTX_DAG_OWNER='***' AIRFLOW_CTX_DAG_ID='tunestream_full_etl_dag' AIRFLOW_CTX_TASK_ID='load_user_dim_table' AIRFLOW_CTX_EXECUTION_DATE='2025-07-24T18:04:15.387612+00:00' AIRFLOW_CTX_TRY_NUMBER='4' AIRFLOW_CTX_DAG_RUN_ID='manual__2025-07-24T18:04:15.387612+00:00'
[2025-07-24T18:34:54.935+0000] {logging_mixin.py:188} INFO - Executing transformation for table: users
[2025-07-24T18:34:54.958+0000] {base.py:83} INFO - Using connection ID 'postgres_local' for task execution.
[2025-07-24T18:34:54.964+0000] {sql.py:450} INFO - Running statement: TRUNCATE TABLE users; INSERT INTO users 
        SELECT distinct userid, firstname, lastname, gender, level
        FROM staging_events
        WHERE page='NextSong' AND userid IS NOT NULL
    , parameters: None
[2025-07-24T18:34:55.006+0000] {taskinstance.py:2698} ERROR - Task failed with exception
Traceback (most recent call last):
  File "/home/airflow/.local/lib/python3.8/site-packages/airflow/models/taskinstance.py", line 433, in _execute_task
    result = execute_callable(context=context, **execute_callable_kwargs)
  File "/home/airflow/.local/lib/python3.8/site-packages/airflow/decorators/base.py", line 241, in execute
    return_value = super().execute(context)
  File "/home/airflow/.local/lib/python3.8/site-packages/airflow/operators/python.py", line 199, in execute
    return_value = self.execute_callable()
  File "/home/airflow/.local/lib/python3.8/site-packages/airflow/operators/python.py", line 216, in execute_callable
    return self.python_callable(*self.op_args, **self.op_kwargs)
  File "/opt/airflow/dags/step12345.py", line 207, in load_user_dim_task
    load_table("postgres_local", "users", SqlQueries.user_table_insert)
  File "/opt/airflow/dags/step12345.py", line 163, in load_table
    postgres_hook.run(sql_formatted)
  File "/home/airflow/.local/lib/python3.8/site-packages/airflow/providers/common/sql/hooks/sql.py", line 398, in run
    self._run_command(cur, sql_statement, parameters)
  File "/home/airflow/.local/lib/python3.8/site-packages/airflow/providers/common/sql/hooks/sql.py", line 455, in _run_command
    cur.execute(sql_statement)
psycopg2.errors.UniqueViolation: duplicate key value violates unique constraint "users_pkey"
DETAIL:  Key (userid)=(88) already exists.

[2025-07-24T18:34:55.066+0000] {taskinstance.py:1138} INFO - Marking task as FAILED. dag_id=tunestream_full_etl_dag, task_id=load_user_dim_table, execution_date=20250724T180415, start_date=20250724T183454, end_date=20250724T183455
[2025-07-24T18:34:55.159+0000] {standard_task_runner.py:107} ERROR - Failed to execute job 98 for task load_user_dim_table (duplicate key value violates unique constraint "users_pkey"
DETAIL:  Key (userid)=(88) already exists.
; 1888)
[2025-07-24T18:34:55.198+0000] {local_task_job_runner.py:234} INFO - Task exited with return code 1
[2025-07-24T18:34:55.226+0000] {taskinstance.py:3280} INFO - 0 downstream tasks scheduled from follow-on schedule check
